Workbook

Sheet Notes
A1: El Cerrito financial statements from audited reports, FY2014-FY2025 (+ unaudited FY2025-26)
A3: HOW TO READ | B3: Blue tabs (GF_) = General Fund only - the City's main operating fund, modified-accrual basis. Green tabs (CW_) = citywide governmental activities, full-accrual basis, including buildings/equipment, long-term debt and pension liabilities. GF_to_Citywide_Bridge walks from one to the other. The GF_ tabs do not depend on the CW_ tabs.
A4: FY2025-26 UNAUDITED | B4: FY2026 columns and blocks (orange, marked UNAUDITED / 2026*) come from the City's FY2025-26 Fourth Quarter General Fund Budget Update (Agenda Bill 8.A, 9/15/2026), not an audited ACFR. They use the City's budget-report classifications, which differ from the ACFR (e.g. ~$1M of cost reimbursements appear as 'Other Financing Sources' rather than charges for services). The original expenditure budget is only available as a total. No FY2026 balance sheet, cash flow or citywide statements exist yet; the ACFR is expected December 2026.
A5: Standards | B5: See Standards_Alignment for how each tab maps to GASB 34, 54, 100, 103, 41, 44, 9, 68/75, 87/96 and GFOA practice, and where it deviates. Stat_Trends reproduces the ACFR statistical-section (GASB 44) schedules and cross-checks them against the City's own FY2025 tables. Template pages: ../templates/ElCerrito_FY2025_ACFR_reference_pages.pdf.
A6: Sources | B6: Audited CAFRs (FY2014-FY2020) and ACFRs (FY2021-FY2025) from elcerrito.gov/Archive.aspx?AMID=76 (PDFs in ../acfr/); FY2026 from ../council-packets/. Page references are in cell comments on year headers.
A7: GF_Operating_Statement | B7: Revenues, expenditures, transfers and change in General Fund fund balance (the government 'P&L').
A8: GF_Balance_Sheet | B8: General Fund assets, liabilities, deferred inflows and fund balance at June 30.
A9: GF_Cash_Flow_Derived | B9: NOT audited - reconstructed indirect-method cash flow (governmental funds have no cash-flow statement under GASB).
A10: GF_Budget_Variance / GF_Variance_Trend | B10: Original vs. final vs. actual by category and year; trend sheet gives cumulative totals with and without FY2026.
A11: GF_to_Citywide_Bridge | B11: General Fund fund balance -> all governmental funds -> plus capital assets, less debt and pension -> citywide net position.
A12: CW_Net_Position | B12: Government-wide Statement of Net Position, governmental activities column (excludes the waste-management enterprise fund), with the due-within-one-year split.
A13: CW_Statement_of_Activities | B13: Expenses by function, program and general revenues, change in net position and restatements, FY2014-FY2025.
A14: CW_Pension_OPEB | B14: CalPERS ten-year schedules (proportionate share, contributions, funded ratio), discount-rate sensitivity, OPEB history.
... A25: Color key | B25: Blue text = transcribed input; black = formula; green = formula linking another tab; light-green rows = tie-out checks (should be 0); orange = unaudited.

Sheet Standards_Alignment
A1: Alignment with governmental GAAP (GASB) and GFOA presentation practice
A2: Governmental GAAP in the U.S. is set by GASB, not FASB. Status: Aligned = follows the standard's format; Partial = follows it with a noted limitation; Supplementary = beyond what GASB requires; Not included = outside this workbook's scope.
A4: Standard / guidance | B4: Requirement (summary) | C4: Where in this workbook | D4: Status | E4: Notes / deviations
A5: GASB 34 - fund financial statements | B5: Governmental funds balance sheet: assets, deferred outflows, liabilities, deferred inflows, fund balances; total liabilities, deferred inflows and fund balances equals total assets. | C5: GF_Balance_Sheet | D5: Aligned | E5: General Fund column only (other governmental funds summarized in GF_to_Citywide_Bridge). No deferred outflows exist in the General Fund.
A6: GASB 34 - statement of revenues, expenditures and changes in fund balances | B6: Revenues by source; expenditures by function (current, capital outlay, debt service principal/interest); excess (deficiency); other financing sources (uses); special items; net change; beginning and ending fund balance. | C6: GF_Operating_Statement | D6: Aligned | E6: Category names standardized across years because the City changed its captions in FY2022 (see GF_Budget_Detail for lines as printed).
A7: GASB 54 - fund balance classification | B7: Nonspendable, restricted, committed, assigned, unassigned. | C7: GF_Balance_Sheet; Stat_Trends Schedule 2 | D7: Aligned | E7: Committed is shown although El Cerrito reports none. The Emergency Disaster Relief reserve is shown as unassigned, as the City reports it.
A8: GASB 100 - accounting changes and error corrections | B8: Display adjustments to beginning balances separately (as previously reported, adjustment, as restated). | C8: GF_Operating_Statement (fund balance section) | D8: Aligned | E8: FY2017, FY2020, FY2023, FY2024 adjustments shown with source comments. GASB 100 applies from FY2024; earlier years are presented the same way for comparability.
A9: GASB 34 / GASB 41 - budgetary comparison (RSI) | B9: General Fund: original budget, final budget, actual on the budgetary basis; variance with final budget encouraged; basis disclosed. | C9: GF_Budget_Variance | D9: Aligned | E9: City budgets on a GAAP basis (ACFR 'Budget and Actual (GAAP Basis)'). FY2026 is on the City's budget-report basis and flagged.
A10: GASB 103 - financial reporting model improvements (FY2026+) | B10: Budgetary comparison as RSI with separate columns for original-to-final and final-to-actual variances; notes explaining significant variances; 'unusual or infrequent items' replaces special/extraordinary items. | C10: GF_Budget_Variance columns E-F and I; GF_Variance_Notes; GF_Operating_Statement | D10: Partial | E10: Both variance columns are present for all years (early application). GF_Variance_Notes explains the major variances FY2019-FY2026 from public sources; smaller flagged lines have no public explanation. 'Special items' caption retained for audited years, with a GASB 103 note.
A11: GASB legal level of budgetary control (GFOA) | B11: Budgetary comparisons at the legal level of control. | C11: GF_Budget_Variance | D11: Aligned | E11: El Cerrito's legal level of budgetary control is the fund level (FY2025 ACFR budgetary note), so the fund totals meet this; category detail is supplementary.
A12: GASB 34 - government-wide statement of net position | B12: Assets, deferred outflows, liabilities, deferred inflows; net position as net investment in capital assets, restricted, unrestricted; long-term liabilities split due within / beyond one year. | C12: CW_Net_Position | D12: Aligned | E12: Liabilities by type with a separate due-within / due-beyond one-year section (bottom of tab). Governmental activities column only.
A13: GASB 34 - statement of activities | B13: Expenses by function, program revenues, general revenues, change in net position. | C13: CW_Statement_of_Activities | D13: Aligned | E13: Expenses, program revenues (charges, operating and capital grants) and net (expense) revenue by function, general revenues, change in net position and restatements, FY2014-FY2025. Grants by function come from each year's basic statement.
A14: GASB 34 - reconciliation of fund balance to net position | B14: Reconcile total governmental fund balances to governmental activities net position. | C14: GF_to_Citywide_Bridge | D14: Aligned | E14: Starts from the General Fund and adds other funds; the bottom section reproduces each year's ACFR reconciliation line by line (capital assets, internal service fund, unavailable revenue, interest, deferrals, debt, leave, claims, OPEB, pension) and ties to net position.
A15: GASB 9 - statement of cash flows | B15: Required for proprietary funds only (operating, noncapital financing, capital and related financing, investing). | C15: GF_Cash_Flow_Derived | D15: Supplementary | E15: Not a GASB requirement for governmental funds; reconstructed using GASB 9 categories and labelled as derived/unaudited.
... A20: Unaudited / preliminary data | B20: Clearly distinguish unaudited figures from audited statements. | C20: FY2026 columns and blocks | D20: Aligned | E20: Orange shading, 'UNAUDITED' labels, separate cumulative totals with and without FY2026.
A22: Templates and references
A23: El Cerrito FY2025 ACFR template pages | B23: ../templates/ElCerrito_FY2025_ACFR_reference_pages.pdf: Statement of Net Position, governmental funds balance sheet, reconciliation, statement of revenues/expenditures, General Fund budgetary comparison, Statistical Tables 1, 3, 4, 10, 13.
A24: GASB 103 summaries | B24: https://weaver.com/resources/are-you-ready-to-implement-the-new-gasb-103-financial-reporting-model-improvements ; https://blog.becpas.com/navigating-gasb-103-key-changes-to-the-financial-reporting-model
A25: GASB 100 summary | B25: https://rsmus.com/insights/financial-reporting/gasb-revises-requirements-for-accounting-changes-and-error-corre.html
A26: GASB 44 statistical section guide | B26: https://www.nj.gov/education/finance/fp/acfr/statguide.pdf
A27: CalPERS valuation reports | B27: https://www.calpers.ca.gov/documents/el-cerrito-city-miscellaneous-2025/download ; https://www.calpers.ca.gov/documents/el-cerrito-city-safety-fire-2025/download (2024 versions at the same address with -2024)
A28: GFOA budget-to-actual guidance | B28: https://gfoa.org/materials/retaining-budget-to-actual-comparisons-within-the-audited

Sheet GF_Operating_Statement
A1: City of El Cerrito - GENERAL FUND ONLY
A2: Statement of Revenues, Expenditures and Changes in Fund Balance (the government 'P&L'), actuals, $
A3: Modified-accrual basis. FY2014-FY2025 audited; FY2026* UNAUDITED (Q4 update, budget-report basis - see Notes). Each figure is a SUMIFS on GF_Budget_Detail. Taxes and Police/Fire are reported combined from FY2022.
N5: UNAUDITED
A6: Fiscal year ended June 30 | B6: 2014 | C6: 2015 | D6: 2016 | E6: 2017 | F6: 2018 | G6: 2019 | H6: 2020 | I6: 2021 | J6: 2022 | K6: 2023 | L6: 2024 | M6: 2025 | N6: 2026
A7: REVENUES
A8: Property taxes | B8: =SUMIFS(GF_Budget_Detail!$G$5:$G$295,GF_Budget_Detail!$A$5:$A$295,B$6,GF_Budget_Detail!$D$5:$D$295,"Property taxes") | C8: =SUMIFS(GF_Budget_Detail!$G$5:$G$295,GF_Budget_Detail!$A$5:$A$295,C$6,GF_Budget_Detail!$D$5:$D$295,"Property taxes") | D8: =SUMIFS(GF_Budget_Detail!$G$5:$G$295,GF_Budget_Detail!$A$5:$A$295,D$6,GF_Budget_Detail!$D$5:$D$295,"Property taxes") | E8: =SUMIFS(GF_Budget_Detail!$G$5:$G$295,GF_Budget_Detail!$A$5:$A$295,E$6,GF_Budget_Detail!$D$5:$D$295,"Property taxes") | F8: =SUMIFS(GF_Budget_Detail!$G$5:$G$295,GF_Budget_Detail!$A$5:$A$295,F$6,GF_Budget_Detail!$D$5:$D$295,"Property taxes") | G8: =SUMIFS(GF_Budget_Detail!$G$5:$G$295,GF_Budget_Detail!$A$5:$A$295,G$6,GF_Budget_Detail!$D$5:$D$295,"Property taxes") | H8: =SUMIFS(GF_Budget_Detail!$G$5:$G$295,GF_Budget_Detail!$A$5:$A$295,H$6,GF_Budget_Detail!$D$5:$D$295,"Property taxes") | I8: =SUMIFS(GF_Budget_Detail!$G$5:$G$295,GF_Budget_Detail!$A$5:$A$295,I$6,GF_Budget_Detail!$D$5:$D$295,"Property taxes") | ... N8: =SUMIFS(GF_Budget_Detail!$G$5:$G$295,GF_Budget_Detail!$A$5:$A$295,N$6,GF_Budget_Detail!$D$5:$D$295,"Property taxes")
A9: Taxes other than property | B9: =SUMIFS(GF_Budget_Detail!$G$5:$G$295,GF_Budget_Detail!$A$5:$A$295,B$6,GF_Budget_Detail!$D$5:$D$295,"Taxes other than property") | C9: =SUMIFS(GF_Budget_Detail!$G$5:$G$295,GF_Budget_Detail!$A$5:$A$295,C$6,GF_Budget_Detail!$D$5:$D$295,"Taxes other than property") | D9: =SUMIFS(GF_Budget_Detail!$G$5:$G$295,GF_Budget_Detail!$A$5:$A$295,D$6,GF_Budget_Detail!$D$5:$D$295,"Taxes other than property") | E9: =SUMIFS(GF_Budget_Detail!$G$5:$G$295,GF_Budget_Detail!$A$5:$A$295,E$6,GF_Budget_Detail!$D$5:$D$295,"Taxes other than property") | F9: =SUMIFS(GF_Budget_Detail!$G$5:$G$295,GF_Budget_Detail!$A$5:$A$295,F$6,GF_Budget_Detail!$D$5:$D$295,"Taxes other than property") | G9: =SUMIFS(GF_Budget_Detail!$G$5:$G$295,GF_Budget_Detail!$A$5:$A$295,G$6,GF_Budget_Detail!$D$5:$D$295,"Taxes other than property") | H9: =SUMIFS(GF_Budget_Detail!$G$5:$G$295,GF_Budget_Detail!$A$5:$A$295,H$6,GF_Budget_Detail!$D$5:$D$295,"Taxes other than property") | I9: =SUMIFS(GF_Budget_Detail!$G$5:$G$295,GF_Budget_Detail!$A$5:$A$295,I$6,GF_Budget_Detail!$D$5:$D$295,"Taxes other than property") | ... N9: =SUMIFS(GF_Budget_Detail!$G$5:$G$295,GF_Budget_Detail!$A$5:$A$295,N$6,GF_Budget_Detail!$D$5:$D$295,"Taxes other than property")
A10: Taxes and assessments (combined) | B10: =SUMIFS(GF_Budget_Detail!$G$5:$G$295,GF_Budget_Detail!$A$5:$A$295,B$6,GF_Budget_Detail!$D$5:$D$295,"Taxes and assessments (combined)") | C10: =SUMIFS(GF_Budget_Detail!$G$5:$G$295,GF_Budget_Detail!$A$5:$A$295,C$6,GF_Budget_Detail!$D$5:$D$295,"Taxes and assessments (combined)") | D10: =SUMIFS(GF_Budget_Detail!$G$5:$G$295,GF_Budget_Detail!$A$5:$A$295,D$6,GF_Budget_Detail!$D$5:$D$295,"Taxes and assessments (combined)") | E10: =SUMIFS(GF_Budget_Detail!$G$5:$G$295,GF_Budget_Detail!$A$5:$A$295,E$6,GF_Budget_Detail!$D$5:$D$295,"Taxes and assessments (combined)") | F10: =SUMIFS(GF_Budget_Detail!$G$5:$G$295,GF_Budget_Detail!$A$5:$A$295,F$6,GF_Budget_Detail!$D$5:$D$295,"Taxes and assessments (combined)") | G10: =SUMIFS(GF_Budget_Detail!$G$5:$G$295,GF_Budget_Detail!$A$5:$A$295,G$6,GF_Budget_Detail!$D$5:$D$295,"Taxes and assessments (combined)") | H10: =SUMIFS(GF_Budget_Detail!$G$5:$G$295,GF_Budget_Detail!$A$5:$A$295,H$6,GF_Budget_Detail!$D$5:$D$295,"Taxes and assessments (combined)") | I10: =SUMIFS(GF_Budget_Detail!$G$5:$G$295,GF_Budget_Detail!$A$5:$A$295,I$6,GF_Budget_Detail!$D$5:$D$295,"Taxes and assessments (combined)") | ... N10: =SUMIFS(GF_Budget_Detail!$G$5:$G$295,GF_Budget_Detail!$A$5:$A$295,N$6,GF_Budget_Detail!$D$5:$D$295,"Taxes and assessments (combined)")
A11: Licenses and permits | B11: =SUMIFS(GF_Budget_Detail!$G$5:$G$295,GF_Budget_Detail!$A$5:$A$295,B$6,GF_Budget_Detail!$D$5:$D$295,"Licenses and permits") | C11: =SUMIFS(GF_Budget_Detail!$G$5:$G$295,GF_Budget_Detail!$A$5:$A$295,C$6,GF_Budget_Detail!$D$5:$D$295,"Licenses and permits") | D11: =SUMIFS(GF_Budget_Detail!$G$5:$G$295,GF_Budget_Detail!$A$5:$A$295,D$6,GF_Budget_Detail!$D$5:$D$295,"Licenses and permits") | E11: =SUMIFS(GF_Budget_Detail!$G$5:$G$295,GF_Budget_Detail!$A$5:$A$295,E$6,GF_Budget_Detail!$D$5:$D$295,"Licenses and permits") | F11: =SUMIFS(GF_Budget_Detail!$G$5:$G$295,GF_Budget_Detail!$A$5:$A$295,F$6,GF_Budget_Detail!$D$5:$D$295,"Licenses and permits") | G11: =SUMIFS(GF_Budget_Detail!$G$5:$G$295,GF_Budget_Detail!$A$5:$A$295,G$6,GF_Budget_Detail!$D$5:$D$295,"Licenses and permits") | H11: =SUMIFS(GF_Budget_Detail!$G$5:$G$295,GF_Budget_Detail!$A$5:$A$295,H$6,GF_Budget_Detail!$D$5:$D$295,"Licenses and permits") | I11: =SUMIFS(GF_Budget_Detail!$G$5:$G$295,GF_Budget_Detail!$A$5:$A$295,I$6,GF_Budget_Detail!$D$5:$D$295,"Licenses and permits") | ... N11: =SUMIFS(GF_Budget_Detail!$G$5:$G$295,GF_Budget_Detail!$A$5:$A$295,N$6,GF_Budget_Detail!$D$5:$D$295,"Licenses and permits")
A12: Fines and forfeitures | B12: =SUMIFS(GF_Budget_Detail!$G$5:$G$295,GF_Budget_Detail!$A$5:$A$295,B$6,GF_Budget_Detail!$D$5:$D$295,"Fines and forfeitures") | C12: =SUMIFS(GF_Budget_Detail!$G$5:$G$295,GF_Budget_Detail!$A$5:$A$295,C$6,GF_Budget_Detail!$D$5:$D$295,"Fines and forfeitures") | D12: =SUMIFS(GF_Budget_Detail!$G$5:$G$295,GF_Budget_Detail!$A$5:$A$295,D$6,GF_Budget_Detail!$D$5:$D$295,"Fines and forfeitures") | E12: =SUMIFS(GF_Budget_Detail!$G$5:$G$295,GF_Budget_Detail!$A$5:$A$295,E$6,GF_Budget_Detail!$D$5:$D$295,"Fines and forfeitures") | F12: =SUMIFS(GF_Budget_Detail!$G$5:$G$295,GF_Budget_Detail!$A$5:$A$295,F$6,GF_Budget_Detail!$D$5:$D$295,"Fines and forfeitures") | G12: =SUMIFS(GF_Budget_Detail!$G$5:$G$295,GF_Budget_Detail!$A$5:$A$295,G$6,GF_Budget_Detail!$D$5:$D$295,"Fines and forfeitures") | H12: =SUMIFS(GF_Budget_Detail!$G$5:$G$295,GF_Budget_Detail!$A$5:$A$295,H$6,GF_Budget_Detail!$D$5:$D$295,"Fines and forfeitures") | I12: =SUMIFS(GF_Budget_Detail!$G$5:$G$295,GF_Budget_Detail!$A$5:$A$295,I$6,GF_Budget_Detail!$D$5:$D$295,"Fines and forfeitures") | ... N12: =SUMIFS(GF_Budget_Detail!$G$5:$G$295,GF_Budget_Detail!$A$5:$A$295,N$6,GF_Budget_Detail!$D$5:$D$295,"Fines and forfeitures")
A13: Use of money and property | B13: =SUMIFS(GF_Budget_Detail!$G$5:$G$295,GF_Budget_Detail!$A$5:$A$295,B$6,GF_Budget_Detail!$D$5:$D$295,"Use of money and property") | C13: =SUMIFS(GF_Budget_Detail!$G$5:$G$295,GF_Budget_Detail!$A$5:$A$295,C$6,GF_Budget_Detail!$D$5:$D$295,"Use of money and property") | D13: =SUMIFS(GF_Budget_Detail!$G$5:$G$295,GF_Budget_Detail!$A$5:$A$295,D$6,GF_Budget_Detail!$D$5:$D$295,"Use of money and property") | E13: =SUMIFS(GF_Budget_Detail!$G$5:$G$295,GF_Budget_Detail!$A$5:$A$295,E$6,GF_Budget_Detail!$D$5:$D$295,"Use of money and property") | F13: =SUMIFS(GF_Budget_Detail!$G$5:$G$295,GF_Budget_Detail!$A$5:$A$295,F$6,GF_Budget_Detail!$D$5:$D$295,"Use of money and property") | G13: =SUMIFS(GF_Budget_Detail!$G$5:$G$295,GF_Budget_Detail!$A$5:$A$295,G$6,GF_Budget_Detail!$D$5:$D$295,"Use of money and property") | H13: =SUMIFS(GF_Budget_Detail!$G$5:$G$295,GF_Budget_Detail!$A$5:$A$295,H$6,GF_Budget_Detail!$D$5:$D$295,"Use of money and property") | I13: =SUMIFS(GF_Budget_Detail!$G$5:$G$295,GF_Budget_Detail!$A$5:$A$295,I$6,GF_Budget_Detail!$D$5:$D$295,"Use of money and property") | ... N13: =SUMIFS(GF_Budget_Detail!$G$5:$G$295,GF_Budget_Detail!$A$5:$A$295,N$6,GF_Budget_Detail!$D$5:$D$295,"Use of money and property")
A14: Intergovernmental | B14: =SUMIFS(GF_Budget_Detail!$G$5:$G$295,GF_Budget_Detail!$A$5:$A$295,B$6,GF_Budget_Detail!$D$5:$D$295,"Intergovernmental") | C14: =SUMIFS(GF_Budget_Detail!$G$5:$G$295,GF_Budget_Detail!$A$5:$A$295,C$6,GF_Budget_Detail!$D$5:$D$295,"Intergovernmental") | D14: =SUMIFS(GF_Budget_Detail!$G$5:$G$295,GF_Budget_Detail!$A$5:$A$295,D$6,GF_Budget_Detail!$D$5:$D$295,"Intergovernmental") | E14: =SUMIFS(GF_Budget_Detail!$G$5:$G$295,GF_Budget_Detail!$A$5:$A$295,E$6,GF_Budget_Detail!$D$5:$D$295,"Intergovernmental") | F14: =SUMIFS(GF_Budget_Detail!$G$5:$G$295,GF_Budget_Detail!$A$5:$A$295,F$6,GF_Budget_Detail!$D$5:$D$295,"Intergovernmental") | G14: =SUMIFS(GF_Budget_Detail!$G$5:$G$295,GF_Budget_Detail!$A$5:$A$295,G$6,GF_Budget_Detail!$D$5:$D$295,"Intergovernmental") | H14: =SUMIFS(GF_Budget_Detail!$G$5:$G$295,GF_Budget_Detail!$A$5:$A$295,H$6,GF_Budget_Detail!$D$5:$D$295,"Intergovernmental") | I14: =SUMIFS(GF_Budget_Detail!$G$5:$G$295,GF_Budget_Detail!$A$5:$A$295,I$6,GF_Budget_Detail!$D$5:$D$295,"Intergovernmental") | ... N14: =SUMIFS(GF_Budget_Detail!$G$5:$G$295,GF_Budget_Detail!$A$5:$A$295,N$6,GF_Budget_Detail!$D$5:$D$295,"Intergovernmental")
A15: Charges for services | B15: =SUMIFS(GF_Budget_Detail!$G$5:$G$295,GF_Budget_Detail!$A$5:$A$295,B$6,GF_Budget_Detail!$D$5:$D$295,"Charges for services") | C15: =SUMIFS(GF_Budget_Detail!$G$5:$G$295,GF_Budget_Detail!$A$5:$A$295,C$6,GF_Budget_Detail!$D$5:$D$295,"Charges for services") | D15: =SUMIFS(GF_Budget_Detail!$G$5:$G$295,GF_Budget_Detail!$A$5:$A$295,D$6,GF_Budget_Detail!$D$5:$D$295,"Charges for services") | E15: =SUMIFS(GF_Budget_Detail!$G$5:$G$295,GF_Budget_Detail!$A$5:$A$295,E$6,GF_Budget_Detail!$D$5:$D$295,"Charges for services") | F15: =SUMIFS(GF_Budget_Detail!$G$5:$G$295,GF_Budget_Detail!$A$5:$A$295,F$6,GF_Budget_Detail!$D$5:$D$295,"Charges for services") | G15: =SUMIFS(GF_Budget_Detail!$G$5:$G$295,GF_Budget_Detail!$A$5:$A$295,G$6,GF_Budget_Detail!$D$5:$D$295,"Charges for services") | H15: =SUMIFS(GF_Budget_Detail!$G$5:$G$295,GF_Budget_Detail!$A$5:$A$295,H$6,GF_Budget_Detail!$D$5:$D$295,"Charges for services") | I15: =SUMIFS(GF_Budget_Detail!$G$5:$G$295,GF_Budget_Detail!$A$5:$A$295,I$6,GF_Budget_Detail!$D$5:$D$295,"Charges for services") | ... N15: =SUMIFS(GF_Budget_Detail!$G$5:$G$295,GF_Budget_Detail!$A$5:$A$295,N$6,GF_Budget_Detail!$D$5:$D$295,"Charges for services")
A16: Other revenues | B16: =SUMIFS(GF_Budget_Detail!$G$5:$G$295,GF_Budget_Detail!$A$5:$A$295,B$6,GF_Budget_Detail!$D$5:$D$295,"Other revenues") | C16: =SUMIFS(GF_Budget_Detail!$G$5:$G$295,GF_Budget_Detail!$A$5:$A$295,C$6,GF_Budget_Detail!$D$5:$D$295,"Other revenues") | D16: =SUMIFS(GF_Budget_Detail!$G$5:$G$295,GF_Budget_Detail!$A$5:$A$295,D$6,GF_Budget_Detail!$D$5:$D$295,"Other revenues") | E16: =SUMIFS(GF_Budget_Detail!$G$5:$G$295,GF_Budget_Detail!$A$5:$A$295,E$6,GF_Budget_Detail!$D$5:$D$295,"Other revenues") | F16: =SUMIFS(GF_Budget_Detail!$G$5:$G$295,GF_Budget_Detail!$A$5:$A$295,F$6,GF_Budget_Detail!$D$5:$D$295,"Other revenues") | G16: =SUMIFS(GF_Budget_Detail!$G$5:$G$295,GF_Budget_Detail!$A$5:$A$295,G$6,GF_Budget_Detail!$D$5:$D$295,"Other revenues") | H16: =SUMIFS(GF_Budget_Detail!$G$5:$G$295,GF_Budget_Detail!$A$5:$A$295,H$6,GF_Budget_Detail!$D$5:$D$295,"Other revenues") | I16: =SUMIFS(GF_Budget_Detail!$G$5:$G$295,GF_Budget_Detail!$A$5:$A$295,I$6,GF_Budget_Detail!$D$5:$D$295,"Other revenues") | ... N16: =SUMIFS(GF_Budget_Detail!$G$5:$G$295,GF_Budget_Detail!$A$5:$A$295,N$6,GF_Budget_Detail!$D$5:$D$295,"Other revenues")
A17: Total revenues | B17: =SUM(B8:B16) | C17: =SUM(C8:C16) | D17: =SUM(D8:D16) | E17: =SUM(E8:E16) | F17: =SUM(F8:F16) | G17: =SUM(G8:G16) | H17: =SUM(H8:H16) | I17: =SUM(I8:I16) | ... N17: =SUM(N8:N16)
A19: EXPENDITURES
A20: Current:
A21: General government | B21: =SUMIFS(GF_Budget_Detail!$G$5:$G$295,GF_Budget_Detail!$A$5:$A$295,B$6,GF_Budget_Detail!$D$5:$D$295,"General government") | C21: =SUMIFS(GF_Budget_Detail!$G$5:$G$295,GF_Budget_Detail!$A$5:$A$295,C$6,GF_Budget_Detail!$D$5:$D$295,"General government") | D21: =SUMIFS(GF_Budget_Detail!$G$5:$G$295,GF_Budget_Detail!$A$5:$A$295,D$6,GF_Budget_Detail!$D$5:$D$295,"General government") | E21: =SUMIFS(GF_Budget_Detail!$G$5:$G$295,GF_Budget_Detail!$A$5:$A$295,E$6,GF_Budget_Detail!$D$5:$D$295,"General government") | F21: =SUMIFS(GF_Budget_Detail!$G$5:$G$295,GF_Budget_Detail!$A$5:$A$295,F$6,GF_Budget_Detail!$D$5:$D$295,"General government") | G21: =SUMIFS(GF_Budget_Detail!$G$5:$G$295,GF_Budget_Detail!$A$5:$A$295,G$6,GF_Budget_Detail!$D$5:$D$295,"General government") | H21: =SUMIFS(GF_Budget_Detail!$G$5:$G$295,GF_Budget_Detail!$A$5:$A$295,H$6,GF_Budget_Detail!$D$5:$D$295,"General government") | I21: =SUMIFS(GF_Budget_Detail!$G$5:$G$295,GF_Budget_Detail!$A$5:$A$295,I$6,GF_Budget_Detail!$D$5:$D$295,"General government") | ... N21: =SUMIFS(GF_Budget_Detail!$G$5:$G$295,GF_Budget_Detail!$A$5:$A$295,N$6,GF_Budget_Detail!$D$5:$D$295,"General government")
A22: Public works | B22: =SUMIFS(GF_Budget_Detail!$G$5:$G$295,GF_Budget_Detail!$A$5:$A$295,B$6,GF_Budget_Detail!$D$5:$D$295,"Public works") | C22: =SUMIFS(GF_Budget_Detail!$G$5:$G$295,GF_Budget_Detail!$A$5:$A$295,C$6,GF_Budget_Detail!$D$5:$D$295,"Public works") | D22: =SUMIFS(GF_Budget_Detail!$G$5:$G$295,GF_Budget_Detail!$A$5:$A$295,D$6,GF_Budget_Detail!$D$5:$D$295,"Public works") | E22: =SUMIFS(GF_Budget_Detail!$G$5:$G$295,GF_Budget_Detail!$A$5:$A$295,E$6,GF_Budget_Detail!$D$5:$D$295,"Public works") | F22: =SUMIFS(GF_Budget_Detail!$G$5:$G$295,GF_Budget_Detail!$A$5:$A$295,F$6,GF_Budget_Detail!$D$5:$D$295,"Public works") | G22: =SUMIFS(GF_Budget_Detail!$G$5:$G$295,GF_Budget_Detail!$A$5:$A$295,G$6,GF_Budget_Detail!$D$5:$D$295,"Public works") | H22: =SUMIFS(GF_Budget_Detail!$G$5:$G$295,GF_Budget_Detail!$A$5:$A$295,H$6,GF_Budget_Detail!$D$5:$D$295,"Public works") | I22: =SUMIFS(GF_Budget_Detail!$G$5:$G$295,GF_Budget_Detail!$A$5:$A$295,I$6,GF_Budget_Detail!$D$5:$D$295,"Public works") | ... N22: =SUMIFS(GF_Budget_Detail!$G$5:$G$295,GF_Budget_Detail!$A$5:$A$295,N$6,GF_Budget_Detail!$D$5:$D$295,"Public works")
A23: Recreation | B23: =SUMIFS(GF_Budget_Detail!$G$5:$G$295,GF_Budget_Detail!$A$5:$A$295,B$6,GF_Budget_Detail!$D$5:$D$295,"Recreation") | C23: =SUMIFS(GF_Budget_Detail!$G$5:$G$295,GF_Budget_Detail!$A$5:$A$295,C$6,GF_Budget_Detail!$D$5:$D$295,"Recreation") | D23: =SUMIFS(GF_Budget_Detail!$G$5:$G$295,GF_Budget_Detail!$A$5:$A$295,D$6,GF_Budget_Detail!$D$5:$D$295,"Recreation") | E23: =SUMIFS(GF_Budget_Detail!$G$5:$G$295,GF_Budget_Detail!$A$5:$A$295,E$6,GF_Budget_Detail!$D$5:$D$295,"Recreation") | F23: =SUMIFS(GF_Budget_Detail!$G$5:$G$295,GF_Budget_Detail!$A$5:$A$295,F$6,GF_Budget_Detail!$D$5:$D$295,"Recreation") | G23: =SUMIFS(GF_Budget_Detail!$G$5:$G$295,GF_Budget_Detail!$A$5:$A$295,G$6,GF_Budget_Detail!$D$5:$D$295,"Recreation") | H23: =SUMIFS(GF_Budget_Detail!$G$5:$G$295,GF_Budget_Detail!$A$5:$A$295,H$6,GF_Budget_Detail!$D$5:$D$295,"Recreation") | I23: =SUMIFS(GF_Budget_Detail!$G$5:$G$295,GF_Budget_Detail!$A$5:$A$295,I$6,GF_Budget_Detail!$D$5:$D$295,"Recreation") | ... N23: =SUMIFS(GF_Budget_Detail!$G$5:$G$295,GF_Budget_Detail!$A$5:$A$295,N$6,GF_Budget_Detail!$D$5:$D$295,"Recreation")
A24: Community development | B24: =SUMIFS(GF_Budget_Detail!$G$5:$G$295,GF_Budget_Detail!$A$5:$A$295,B$6,GF_Budget_Detail!$D$5:$D$295,"Community development") | C24: =SUMIFS(GF_Budget_Detail!$G$5:$G$295,GF_Budget_Detail!$A$5:$A$295,C$6,GF_Budget_Detail!$D$5:$D$295,"Community development") | D24: =SUMIFS(GF_Budget_Detail!$G$5:$G$295,GF_Budget_Detail!$A$5:$A$295,D$6,GF_Budget_Detail!$D$5:$D$295,"Community development") | E24: =SUMIFS(GF_Budget_Detail!$G$5:$G$295,GF_Budget_Detail!$A$5:$A$295,E$6,GF_Budget_Detail!$D$5:$D$295,"Community development") | F24: =SUMIFS(GF_Budget_Detail!$G$5:$G$295,GF_Budget_Detail!$A$5:$A$295,F$6,GF_Budget_Detail!$D$5:$D$295,"Community development") | G24: =SUMIFS(GF_Budget_Detail!$G$5:$G$295,GF_Budget_Detail!$A$5:$A$295,G$6,GF_Budget_Detail!$D$5:$D$295,"Community development") | H24: =SUMIFS(GF_Budget_Detail!$G$5:$G$295,GF_Budget_Detail!$A$5:$A$295,H$6,GF_Budget_Detail!$D$5:$D$295,"Community development") | I24: =SUMIFS(GF_Budget_Detail!$G$5:$G$295,GF_Budget_Detail!$A$5:$A$295,I$6,GF_Budget_Detail!$D$5:$D$295,"Community development") | ... N24: =SUMIFS(GF_Budget_Detail!$G$5:$G$295,GF_Budget_Detail!$A$5:$A$295,N$6,GF_Budget_Detail!$D$5:$D$295,"Community development")
A25: Public safety - Police | B25: =SUMIFS(GF_Budget_Detail!$G$5:$G$295,GF_Budget_Detail!$A$5:$A$295,B$6,GF_Budget_Detail!$D$5:$D$295,"Public safety - Police") | C25: =SUMIFS(GF_Budget_Detail!$G$5:$G$295,GF_Budget_Detail!$A$5:$A$295,C$6,GF_Budget_Detail!$D$5:$D$295,"Public safety - Police") | D25: =SUMIFS(GF_Budget_Detail!$G$5:$G$295,GF_Budget_Detail!$A$5:$A$295,D$6,GF_Budget_Detail!$D$5:$D$295,"Public safety - Police") | E25: =SUMIFS(GF_Budget_Detail!$G$5:$G$295,GF_Budget_Detail!$A$5:$A$295,E$6,GF_Budget_Detail!$D$5:$D$295,"Public safety - Police") | F25: =SUMIFS(GF_Budget_Detail!$G$5:$G$295,GF_Budget_Detail!$A$5:$A$295,F$6,GF_Budget_Detail!$D$5:$D$295,"Public safety - Police") | G25: =SUMIFS(GF_Budget_Detail!$G$5:$G$295,GF_Budget_Detail!$A$5:$A$295,G$6,GF_Budget_Detail!$D$5:$D$295,"Public safety - Police") | H25: =SUMIFS(GF_Budget_Detail!$G$5:$G$295,GF_Budget_Detail!$A$5:$A$295,H$6,GF_Budget_Detail!$D$5:$D$295,"Public safety - Police") | I25: =SUMIFS(GF_Budget_Detail!$G$5:$G$295,GF_Budget_Detail!$A$5:$A$295,I$6,GF_Budget_Detail!$D$5:$D$295,"Public safety - Police") | ... N25: =SUMIFS(GF_Budget_Detail!$G$5:$G$295,GF_Budget_Detail!$A$5:$A$295,N$6,GF_Budget_Detail!$D$5:$D$295,"Public safety - Police")
A26: Public safety - Fire | B26: =SUMIFS(GF_Budget_Detail!$G$5:$G$295,GF_Budget_Detail!$A$5:$A$295,B$6,GF_Budget_Detail!$D$5:$D$295,"Public safety - Fire") | C26: =SUMIFS(GF_Budget_Detail!$G$5:$G$295,GF_Budget_Detail!$A$5:$A$295,C$6,GF_Budget_Detail!$D$5:$D$295,"Public safety - Fire") | D26: =SUMIFS(GF_Budget_Detail!$G$5:$G$295,GF_Budget_Detail!$A$5:$A$295,D$6,GF_Budget_Detail!$D$5:$D$295,"Public safety - Fire") | E26: =SUMIFS(GF_Budget_Detail!$G$5:$G$295,GF_Budget_Detail!$A$5:$A$295,E$6,GF_Budget_Detail!$D$5:$D$295,"Public safety - Fire") | F26: =SUMIFS(GF_Budget_Detail!$G$5:$G$295,GF_Budget_Detail!$A$5:$A$295,F$6,GF_Budget_Detail!$D$5:$D$295,"Public safety - Fire") | G26: =SUMIFS(GF_Budget_Detail!$G$5:$G$295,GF_Budget_Detail!$A$5:$A$295,G$6,GF_Budget_Detail!$D$5:$D$295,"Public safety - Fire") | H26: =SUMIFS(GF_Budget_Detail!$G$5:$G$295,GF_Budget_Detail!$A$5:$A$295,H$6,GF_Budget_Detail!$D$5:$D$295,"Public safety - Fire") | I26: =SUMIFS(GF_Budget_Detail!$G$5:$G$295,GF_Budget_Detail!$A$5:$A$295,I$6,GF_Budget_Detail!$D$5:$D$295,"Public safety - Fire") | ... N26: =SUMIFS(GF_Budget_Detail!$G$5:$G$295,GF_Budget_Detail!$A$5:$A$295,N$6,GF_Budget_Detail!$D$5:$D$295,"Public safety - Fire")
A27: Public safety (combined) | B27: =SUMIFS(GF_Budget_Detail!$G$5:$G$295,GF_Budget_Detail!$A$5:$A$295,B$6,GF_Budget_Detail!$D$5:$D$295,"Public safety (combined)") | C27: =SUMIFS(GF_Budget_Detail!$G$5:$G$295,GF_Budget_Detail!$A$5:$A$295,C$6,GF_Budget_Detail!$D$5:$D$295,"Public safety (combined)") | D27: =SUMIFS(GF_Budget_Detail!$G$5:$G$295,GF_Budget_Detail!$A$5:$A$295,D$6,GF_Budget_Detail!$D$5:$D$295,"Public safety (combined)") | E27: =SUMIFS(GF_Budget_Detail!$G$5:$G$295,GF_Budget_Detail!$A$5:$A$295,E$6,GF_Budget_Detail!$D$5:$D$295,"Public safety (combined)") | F27: =SUMIFS(GF_Budget_Detail!$G$5:$G$295,GF_Budget_Detail!$A$5:$A$295,F$6,GF_Budget_Detail!$D$5:$D$295,"Public safety (combined)") | G27: =SUMIFS(GF_Budget_Detail!$G$5:$G$295,GF_Budget_Detail!$A$5:$A$295,G$6,GF_Budget_Detail!$D$5:$D$295,"Public safety (combined)") | H27: =SUMIFS(GF_Budget_Detail!$G$5:$G$295,GF_Budget_Detail!$A$5:$A$295,H$6,GF_Budget_Detail!$D$5:$D$295,"Public safety (combined)") | I27: =SUMIFS(GF_Budget_Detail!$G$5:$G$295,GF_Budget_Detail!$A$5:$A$295,I$6,GF_Budget_Detail!$D$5:$D$295,"Public safety (combined)") | ... N27: =SUMIFS(GF_Budget_Detail!$G$5:$G$295,GF_Budget_Detail!$A$5:$A$295,N$6,GF_Budget_Detail!$D$5:$D$295,"Public safety (combined)")
A28: Payment of sales tax to City of Richmond | B28: =SUMIFS(GF_Budget_Detail!$G$5:$G$295,GF_Budget_Detail!$A$5:$A$295,B$6,GF_Budget_Detail!$D$5:$D$295,"Payment of sales tax to City of Richmond") | C28: =SUMIFS(GF_Budget_Detail!$G$5:$G$295,GF_Budget_Detail!$A$5:$A$295,C$6,GF_Budget_Detail!$D$5:$D$295,"Payment of sales tax to City of Richmond") | D28: =SUMIFS(GF_Budget_Detail!$G$5:$G$295,GF_Budget_Detail!$A$5:$A$295,D$6,GF_Budget_Detail!$D$5:$D$295,"Payment of sales tax to City of Richmond") | E28: =SUMIFS(GF_Budget_Detail!$G$5:$G$295,GF_Budget_Detail!$A$5:$A$295,E$6,GF_Budget_Detail!$D$5:$D$295,"Payment of sales tax to City of Richmond") | F28: =SUMIFS(GF_Budget_Detail!$G$5:$G$295,GF_Budget_Detail!$A$5:$A$295,F$6,GF_Budget_Detail!$D$5:$D$295,"Payment of sales tax to City of Richmond") | G28: =SUMIFS(GF_Budget_Detail!$G$5:$G$295,GF_Budget_Detail!$A$5:$A$295,G$6,GF_Budget_Detail!$D$5:$D$295,"Payment of sales tax to City of Richmond") | H28: =SUMIFS(GF_Budget_Detail!$G$5:$G$295,GF_Budget_Detail!$A$5:$A$295,H$6,GF_Budget_Detail!$D$5:$D$295,"Payment of sales tax to City of Richmond") | I28: =SUMIFS(GF_Budget_Detail!$G$5:$G$295,GF_Budget_Detail!$A$5:$A$295,I$6,GF_Budget_Detail!$D$5:$D$295,"Payment of sales tax to City of Richmond") | ... N28: =SUMIFS(GF_Budget_Detail!$G$5:$G$295,GF_Budget_Detail!$A$5:$A$295,N$6,GF_Budget_Detail!$D$5:$D$295,"Payment of sales tax to City of Richmond")
A29: Non-departmental (budget-report basis) | B29: =SUMIFS(GF_Budget_Detail!$G$5:$G$295,GF_Budget_Detail!$A$5:$A$295,B$6,GF_Budget_Detail!$D$5:$D$295,"Non-departmental (budget-report basis)") | C29: =SUMIFS(GF_Budget_Detail!$G$5:$G$295,GF_Budget_Detail!$A$5:$A$295,C$6,GF_Budget_Detail!$D$5:$D$295,"Non-departmental (budget-report basis)") | D29: =SUMIFS(GF_Budget_Detail!$G$5:$G$295,GF_Budget_Detail!$A$5:$A$295,D$6,GF_Budget_Detail!$D$5:$D$295,"Non-departmental (budget-report basis)") | E29: =SUMIFS(GF_Budget_Detail!$G$5:$G$295,GF_Budget_Detail!$A$5:$A$295,E$6,GF_Budget_Detail!$D$5:$D$295,"Non-departmental (budget-report basis)") | F29: =SUMIFS(GF_Budget_Detail!$G$5:$G$295,GF_Budget_Detail!$A$5:$A$295,F$6,GF_Budget_Detail!$D$5:$D$295,"Non-departmental (budget-report basis)") | G29: =SUMIFS(GF_Budget_Detail!$G$5:$G$295,GF_Budget_Detail!$A$5:$A$295,G$6,GF_Budget_Detail!$D$5:$D$295,"Non-departmental (budget-report basis)") | H29: =SUMIFS(GF_Budget_Detail!$G$5:$G$295,GF_Budget_Detail!$A$5:$A$295,H$6,GF_Budget_Detail!$D$5:$D$295,"Non-departmental (budget-report basis)") | I29: =SUMIFS(GF_Budget_Detail!$G$5:$G$295,GF_Budget_Detail!$A$5:$A$295,I$6,GF_Budget_Detail!$D$5:$D$295,"Non-departmental (budget-report basis)") | ... N29: =SUMIFS(GF_Budget_Detail!$G$5:$G$295,GF_Budget_Detail!$A$5:$A$295,N$6,GF_Budget_Detail!$D$5:$D$295,"Non-departmental (budget-report basis)")
A30: Capital outlay | B30: =SUMIFS(GF_Budget_Detail!$G$5:$G$295,GF_Budget_Detail!$A$5:$A$295,B$6,GF_Budget_Detail!$D$5:$D$295,"Capital outlay") | C30: =SUMIFS(GF_Budget_Detail!$G$5:$G$295,GF_Budget_Detail!$A$5:$A$295,C$6,GF_Budget_Detail!$D$5:$D$295,"Capital outlay") | D30: =SUMIFS(GF_Budget_Detail!$G$5:$G$295,GF_Budget_Detail!$A$5:$A$295,D$6,GF_Budget_Detail!$D$5:$D$295,"Capital outlay") | E30: =SUMIFS(GF_Budget_Detail!$G$5:$G$295,GF_Budget_Detail!$A$5:$A$295,E$6,GF_Budget_Detail!$D$5:$D$295,"Capital outlay") | F30: =SUMIFS(GF_Budget_Detail!$G$5:$G$295,GF_Budget_Detail!$A$5:$A$295,F$6,GF_Budget_Detail!$D$5:$D$295,"Capital outlay") | G30: =SUMIFS(GF_Budget_Detail!$G$5:$G$295,GF_Budget_Detail!$A$5:$A$295,G$6,GF_Budget_Detail!$D$5:$D$295,"Capital outlay") | H30: =SUMIFS(GF_Budget_Detail!$G$5:$G$295,GF_Budget_Detail!$A$5:$A$295,H$6,GF_Budget_Detail!$D$5:$D$295,"Capital outlay") | I30: =SUMIFS(GF_Budget_Detail!$G$5:$G$295,GF_Budget_Detail!$A$5:$A$295,I$6,GF_Budget_Detail!$D$5:$D$295,"Capital outlay") | ... N30: =SUMIFS(GF_Budget_Detail!$G$5:$G$295,GF_Budget_Detail!$A$5:$A$295,N$6,GF_Budget_Detail!$D$5:$D$295,"Capital outlay")
A31: Debt service:
A32: Principal | B32: =SUMIFS(GF_Budget_Detail!$G$5:$G$295,GF_Budget_Detail!$A$5:$A$295,B$6,GF_Budget_Detail!$D$5:$D$295,"Debt service - principal") | C32: =SUMIFS(GF_Budget_Detail!$G$5:$G$295,GF_Budget_Detail!$A$5:$A$295,C$6,GF_Budget_Detail!$D$5:$D$295,"Debt service - principal") | D32: =SUMIFS(GF_Budget_Detail!$G$5:$G$295,GF_Budget_Detail!$A$5:$A$295,D$6,GF_Budget_Detail!$D$5:$D$295,"Debt service - principal") | E32: =SUMIFS(GF_Budget_Detail!$G$5:$G$295,GF_Budget_Detail!$A$5:$A$295,E$6,GF_Budget_Detail!$D$5:$D$295,"Debt service - principal") | F32: =SUMIFS(GF_Budget_Detail!$G$5:$G$295,GF_Budget_Detail!$A$5:$A$295,F$6,GF_Budget_Detail!$D$5:$D$295,"Debt service - principal") | G32: =SUMIFS(GF_Budget_Detail!$G$5:$G$295,GF_Budget_Detail!$A$5:$A$295,G$6,GF_Budget_Detail!$D$5:$D$295,"Debt service - principal") | H32: =SUMIFS(GF_Budget_Detail!$G$5:$G$295,GF_Budget_Detail!$A$5:$A$295,H$6,GF_Budget_Detail!$D$5:$D$295,"Debt service - principal") | I32: =SUMIFS(GF_Budget_Detail!$G$5:$G$295,GF_Budget_Detail!$A$5:$A$295,I$6,GF_Budget_Detail!$D$5:$D$295,"Debt service - principal") | ... N32: =SUMIFS(GF_Budget_Detail!$G$5:$G$295,GF_Budget_Detail!$A$5:$A$295,N$6,GF_Budget_Detail!$D$5:$D$295,"Debt service - principal")
A33: Interest and fiscal charges | B33: =SUMIFS(GF_Budget_Detail!$G$5:$G$295,GF_Budget_Detail!$A$5:$A$295,B$6,GF_Budget_Detail!$D$5:$D$295,"Debt service - interest") | C33: =SUMIFS(GF_Budget_Detail!$G$5:$G$295,GF_Budget_Detail!$A$5:$A$295,C$6,GF_Budget_Detail!$D$5:$D$295,"Debt service - interest") | D33: =SUMIFS(GF_Budget_Detail!$G$5:$G$295,GF_Budget_Detail!$A$5:$A$295,D$6,GF_Budget_Detail!$D$5:$D$295,"Debt service - interest") | E33: =SUMIFS(GF_Budget_Detail!$G$5:$G$295,GF_Budget_Detail!$A$5:$A$295,E$6,GF_Budget_Detail!$D$5:$D$295,"Debt service - interest") | F33: =SUMIFS(GF_Budget_Detail!$G$5:$G$295,GF_Budget_Detail!$A$5:$A$295,F$6,GF_Budget_Detail!$D$5:$D$295,"Debt service - interest") | G33: =SUMIFS(GF_Budget_Detail!$G$5:$G$295,GF_Budget_Detail!$A$5:$A$295,G$6,GF_Budget_Detail!$D$5:$D$295,"Debt service - interest") | H33: =SUMIFS(GF_Budget_Detail!$G$5:$G$295,GF_Budget_Detail!$A$5:$A$295,H$6,GF_Budget_Detail!$D$5:$D$295,"Debt service - interest") | I33: =SUMIFS(GF_Budget_Detail!$G$5:$G$295,GF_Budget_Detail!$A$5:$A$295,I$6,GF_Budget_Detail!$D$5:$D$295,"Debt service - interest") | ... N33: =SUMIFS(GF_Budget_Detail!$G$5:$G$295,GF_Budget_Detail!$A$5:$A$295,N$6,GF_Budget_Detail!$D$5:$D$295,"Debt service - interest")
A34: Total expenditures | B34: =SUM(B20:B33) | C34: =SUM(C20:C33) | D34: =SUM(D20:D33) | E34: =SUM(E20:E33) | F34: =SUM(F20:F33) | G34: =SUM(G20:G33) | H34: =SUM(H20:H33) | I34: =SUM(I20:I33) | ... N34: =SUM(N20:N33)
A36: Excess (deficiency) of revenues over (under) expenditures | B36: =B17-B34 | C36: =C17-C34 | D36: =D17-D34 | E36: =E17-E34 | F36: =F17-F34 | G36: =G17-G34 | H36: =H17-H34 | I36: =I17-I34 | ... N36: =N17-N34
A38: OTHER FINANCING SOURCES (USES)
A39: Transfers in | B39: =SUMIFS(GF_Budget_Detail!$G$5:$G$295,GF_Budget_Detail!$A$5:$A$295,B$6,GF_Budget_Detail!$D$5:$D$295,"Transfers in") | C39: =SUMIFS(GF_Budget_Detail!$G$5:$G$295,GF_Budget_Detail!$A$5:$A$295,C$6,GF_Budget_Detail!$D$5:$D$295,"Transfers in") | D39: =SUMIFS(GF_Budget_Detail!$G$5:$G$295,GF_Budget_Detail!$A$5:$A$295,D$6,GF_Budget_Detail!$D$5:$D$295,"Transfers in") | E39: =SUMIFS(GF_Budget_Detail!$G$5:$G$295,GF_Budget_Detail!$A$5:$A$295,E$6,GF_Budget_Detail!$D$5:$D$295,"Transfers in") | F39: =SUMIFS(GF_Budget_Detail!$G$5:$G$295,GF_Budget_Detail!$A$5:$A$295,F$6,GF_Budget_Detail!$D$5:$D$295,"Transfers in") | G39: =SUMIFS(GF_Budget_Detail!$G$5:$G$295,GF_Budget_Detail!$A$5:$A$295,G$6,GF_Budget_Detail!$D$5:$D$295,"Transfers in") | H39: =SUMIFS(GF_Budget_Detail!$G$5:$G$295,GF_Budget_Detail!$A$5:$A$295,H$6,GF_Budget_Detail!$D$5:$D$295,"Transfers in") | I39: =SUMIFS(GF_Budget_Detail!$G$5:$G$295,GF_Budget_Detail!$A$5:$A$295,I$6,GF_Budget_Detail!$D$5:$D$295,"Transfers in") | ... N39: =SUMIFS(GF_Budget_Detail!$G$5:$G$295,GF_Budget_Detail!$A$5:$A$295,N$6,GF_Budget_Detail!$D$5:$D$295,"Transfers in")
A40: Transfers out | B40: =SUMIFS(GF_Budget_Detail!$G$5:$G$295,GF_Budget_Detail!$A$5:$A$295,B$6,GF_Budget_Detail!$D$5:$D$295,"Transfers out") | C40: =SUMIFS(GF_Budget_Detail!$G$5:$G$295,GF_Budget_Detail!$A$5:$A$295,C$6,GF_Budget_Detail!$D$5:$D$295,"Transfers out") | D40: =SUMIFS(GF_Budget_Detail!$G$5:$G$295,GF_Budget_Detail!$A$5:$A$295,D$6,GF_Budget_Detail!$D$5:$D$295,"Transfers out") | E40: =SUMIFS(GF_Budget_Detail!$G$5:$G$295,GF_Budget_Detail!$A$5:$A$295,E$6,GF_Budget_Detail!$D$5:$D$295,"Transfers out") | F40: =SUMIFS(GF_Budget_Detail!$G$5:$G$295,GF_Budget_Detail!$A$5:$A$295,F$6,GF_Budget_Detail!$D$5:$D$295,"Transfers out") | G40: =SUMIFS(GF_Budget_Detail!$G$5:$G$295,GF_Budget_Detail!$A$5:$A$295,G$6,GF_Budget_Detail!$D$5:$D$295,"Transfers out") | H40: =SUMIFS(GF_Budget_Detail!$G$5:$G$295,GF_Budget_Detail!$A$5:$A$295,H$6,GF_Budget_Detail!$D$5:$D$295,"Transfers out") | I40: =SUMIFS(GF_Budget_Detail!$G$5:$G$295,GF_Budget_Detail!$A$5:$A$295,I$6,GF_Budget_Detail!$D$5:$D$295,"Transfers out") | ... N40: =SUMIFS(GF_Budget_Detail!$G$5:$G$295,GF_Budget_Detail!$A$5:$A$295,N$6,GF_Budget_Detail!$D$5:$D$295,"Transfers out")
A41: Debt issuance / lease financing | B41: =SUMIFS(GF_Budget_Detail!$G$5:$G$295,GF_Budget_Detail!$A$5:$A$295,B$6,GF_Budget_Detail!$D$5:$D$295,"Debt / lease financing proceeds") | C41: =SUMIFS(GF_Budget_Detail!$G$5:$G$295,GF_Budget_Detail!$A$5:$A$295,C$6,GF_Budget_Detail!$D$5:$D$295,"Debt / lease financing proceeds") | D41: =SUMIFS(GF_Budget_Detail!$G$5:$G$295,GF_Budget_Detail!$A$5:$A$295,D$6,GF_Budget_Detail!$D$5:$D$295,"Debt / lease financing proceeds") | E41: =SUMIFS(GF_Budget_Detail!$G$5:$G$295,GF_Budget_Detail!$A$5:$A$295,E$6,GF_Budget_Detail!$D$5:$D$295,"Debt / lease financing proceeds") | F41: =SUMIFS(GF_Budget_Detail!$G$5:$G$295,GF_Budget_Detail!$A$5:$A$295,F$6,GF_Budget_Detail!$D$5:$D$295,"Debt / lease financing proceeds") | G41: =SUMIFS(GF_Budget_Detail!$G$5:$G$295,GF_Budget_Detail!$A$5:$A$295,G$6,GF_Budget_Detail!$D$5:$D$295,"Debt / lease financing proceeds") | H41: =SUMIFS(GF_Budget_Detail!$G$5:$G$295,GF_Budget_Detail!$A$5:$A$295,H$6,GF_Budget_Detail!$D$5:$D$295,"Debt / lease financing proceeds") | I41: =SUMIFS(GF_Budget_Detail!$G$5:$G$295,GF_Budget_Detail!$A$5:$A$295,I$6,GF_Budget_Detail!$D$5:$D$295,"Debt / lease financing proceeds") | ... N41: =SUMIFS(GF_Budget_Detail!$G$5:$G$295,GF_Budget_Detail!$A$5:$A$295,N$6,GF_Budget_Detail!$D$5:$D$295,"Debt / lease financing proceeds")
A42: Proceeds from sale of capital assets | B42: =SUMIFS(GF_Budget_Detail!$G$5:$G$295,GF_Budget_Detail!$A$5:$A$295,B$6,GF_Budget_Detail!$D$5:$D$295,"Proceeds from sale of capital assets") | C42: =SUMIFS(GF_Budget_Detail!$G$5:$G$295,GF_Budget_Detail!$A$5:$A$295,C$6,GF_Budget_Detail!$D$5:$D$295,"Proceeds from sale of capital assets") | D42: =SUMIFS(GF_Budget_Detail!$G$5:$G$295,GF_Budget_Detail!$A$5:$A$295,D$6,GF_Budget_Detail!$D$5:$D$295,"Proceeds from sale of capital assets") | E42: =SUMIFS(GF_Budget_Detail!$G$5:$G$295,GF_Budget_Detail!$A$5:$A$295,E$6,GF_Budget_Detail!$D$5:$D$295,"Proceeds from sale of capital assets") | F42: =SUMIFS(GF_Budget_Detail!$G$5:$G$295,GF_Budget_Detail!$A$5:$A$295,F$6,GF_Budget_Detail!$D$5:$D$295,"Proceeds from sale of capital assets") | G42: =SUMIFS(GF_Budget_Detail!$G$5:$G$295,GF_Budget_Detail!$A$5:$A$295,G$6,GF_Budget_Detail!$D$5:$D$295,"Proceeds from sale of capital assets") | H42: =SUMIFS(GF_Budget_Detail!$G$5:$G$295,GF_Budget_Detail!$A$5:$A$295,H$6,GF_Budget_Detail!$D$5:$D$295,"Proceeds from sale of capital assets") | I42: =SUMIFS(GF_Budget_Detail!$G$5:$G$295,GF_Budget_Detail!$A$5:$A$295,I$6,GF_Budget_Detail!$D$5:$D$295,"Proceeds from sale of capital assets") | ... N42: =SUMIFS(GF_Budget_Detail!$G$5:$G$295,GF_Budget_Detail!$A$5:$A$295,N$6,GF_Budget_Detail!$D$5:$D$295,"Proceeds from sale of capital assets")
A43: Total other financing sources (uses) | B43: =SUM(B39:B42) | C43: =SUM(C39:C42) | D43: =SUM(D39:D42) | E43: =SUM(E39:E42) | F43: =SUM(F39:F42) | G43: =SUM(G39:G42) | H43: =SUM(H39:H42) | I43: =SUM(I39:I42) | ... N43: =SUM(N39:N42)
A45: SPECIAL ITEMS (GASB 34; 'unusual or infrequent items' under GASB 103 from FY2026)
...

Sheet GF_Balance_Sheet
A1: City of El Cerrito - GENERAL FUND ONLY
A2: Balance Sheet, June 30, $ (General Fund column of the Governmental Funds Balance Sheet)
A3: Modified-accrual fund statement: excludes buildings/equipment, long-term debt and pension liabilities (see the CW_ tabs for those). No FY2025-26 balance sheet has been published yet (unaudited Q4 update reports only the projected ending fund balance).
A6: June 30 | B6: 2014 | C6: 2015 | D6: 2016 | E6: 2017 | F6: 2018 | G6: 2019 | H6: 2020 | I6: 2021 | J6: 2022 | K6: 2023 | L6: 2024 | M6: 2025
A7: ASSETS
A8: Cash and investments | B8: 1 | C8: 1 | D8: 5116309 | E8: 3107248 | F8: 3419338 | G8: 4349089 | H8: 9016794 | I8: 13011276 | J8: 23310907 | K8: 24481528 | L8: 25339004 | M8: 25387360
A9: Cash with fiscal agents | B9: 150445 | C9: 10170 | D9: 10187 | E9: 10205 | F9: 0 | G9: 0 | H9: 0 | I9: 0 | J9: 0 | K9: 0 | L9: 0 | M9: 0
A10: Accounts receivable | B10: 187946 | C10: 29493 | D10: 155287 | E10: 3743 | F10: 9530 | G10: 0 | H10: 633574 | I10: 0 | J10: 6747 | K10: 0 | L10: 1078 | M10: 1890204
A11: Interest receivable | B11: 1 | C11: 0 | D11: 0 | E11: 0 | F11: 0 | G11: 0 | H11: 32158 | I11: 11858 | J11: 24077 | K11: 203968 | L11: 272482 | M11: 220648
A12: Due from other governments | B12: 1747713 | C12: 3253667 | D12: 1663837 | E12: 2348549 | F12: 2778497 | G12: 2113059 | H12: 1249313 | I12: 2955585 | J12: 1027427 | K12: 3481165 | L12: 3291852 | M12: 1952392
A13: Due from other funds | B13: 310035 | C13: 0 | D13: 1270421 | E13: 1671263 | F13: 385338 | G13: 951617 | H13: 374902 | I13: 2846549 | J13: 3051028 | K13: 303058 | L13: 0 | M13: 467019
A14: Advances to other funds | B14: 0 | C14: 0 | D14: 0 | E14: 0 | F14: 988351 | G14: 317967 | H14: 315306 | I14: 0 | J14: 0 | K14: 0 | L14: 0 | M14: 0
A15: Advance to Successor Agency (former RDA) | B15: 0 | C15: 0 | D15: 0 | E15: 873766 | F15: 1321189 | G15: 1321189 | H15: 1321189 | I15: 0 | J15: 0 | K15: 0 | L15: 0 | M15: 0
A16: Inventory | B16: 26965 | C16: 73942 | D16: 110975 | E16: 23595 | F16: 11537 | G16: 11772 | H16: 27737 | I16: 25694 | J16: 38763 | K16: 46338 | L16: 0 | M16: 0
A17: Prepaid items and other assets | B17: 31361 | C17: 54300 | D17: 59378 | E17: 97381 | F17: 0 | G17: 0 | H17: 3279 | I17: 0 | J17: 161576 | K17: 62527 | L17: 138615 | M17: 187240
A18: Total assets | B18: =SUM(B8:B17) | C18: =SUM(C8:C17) | D18: =SUM(D8:D17) | E18: =SUM(E8:E17) | F18: =SUM(F8:F17) | G18: =SUM(G8:G17) | H18: =SUM(H8:H17) | I18: =SUM(I8:I17) | ... M18: =SUM(M8:M17)
A20: LIABILITIES
A21: Accounts payable | B21: 596507 | C21: 732767 | D21: 883120 | E21: 524897 | F21: 346261 | G21: 888579 | H21: 844519 | I21: 806511 | J21: 1248347 | K21: 899927 | L21: 745552 | M21: 1424412
A22: Accrued liabilities | B22: 34074 | C22: 47553 | D22: 61268 | E22: 1081986 | F22: 1102088 | G22: 1231944 | H22: 1551848 | I22: 398547 | J22: 1589666 | K22: 970665 | L22: 1390950 | M22: 1063940
A23: Due to other funds | B23: 250000 | C23: 849386 | D23: 0 | E23: 0 | F23: 0 | G23: 0 | H23: 0 | I23: 0 | J23: 0 | K23: 0 | L23: 0 | M23: 0
A24: Deposits payable | B24: 272842 | C24: 296624 | D24: 500482 | E24: 515730 | F24: 645593 | G24: 804162 | H24: 1605016 | I24: 1759634 | J24: 2006664 | K24: 2222396 | L24: 2465295 | M24: 2394927
A25: Unearned revenue | B25: 30578 | C25: 33731 | D25: 47682 | E25: 47389 | F25: 65497 | G25: 80381 | H25: 82890 | I25: 83463 | J25: 90782 | K25: 1342515 | L25: 1251292 | M25: 729770
A26: Note payable (short-term TRAN) | B26: 0 | C26: 0 | D26: 5000000 | E26: 5000000 | F26: 6000000 | G26: 6000000 | H26: 9000000 | I26: 8659545 | J26: 6060892 | K26: 0 | L26: 0 | M26: 0
A27: Total liabilities | B27: =SUM(B21:B26) | C27: =SUM(C21:C26) | D27: =SUM(D21:D26) | E27: =SUM(E21:E26) | F27: =SUM(F21:F26) | G27: =SUM(G21:G26) | H27: =SUM(H21:H26) | I27: =SUM(I21:I26) | ... M27: =SUM(M21:M26)
A29: DEFERRED INFLOWS OF RESOURCES
A30: Unavailable revenue | B30: 0 | C30: 0 | D30: 0 | E30: 147028 | F30: 666771 | G30: 116319 | H30: 0 | I30: 0 | J30: 0 | K30: 0 | L30: 296604 | M30: 241306
A31: Total deferred inflows | B31: =SUM(B30:B30) | C31: =SUM(C30:C30) | D31: =SUM(D30:D30) | E31: =SUM(E30:E30) | F31: =SUM(F30:F30) | G31: =SUM(G30:G30) | H31: =SUM(H30:H30) | I31: =SUM(I30:I30) | ... M31: =SUM(M30:M30)
A33: FUND BALANCE
A34: Nonspendable | B34: 58326 | C34: 128242 | D34: 170353 | E34: 994742 | F34: 2321077 | G34: 1650928 | H34: 1667511 | I34: 25694 | J34: 200339 | K34: 108865 | L34: 126751 | M34: 175376
A35: Restricted | B35: 150445 | C35: 10170 | D35: 10187 | E35: 10205 | F35: 0 | G35: 0 | H35: 0 | I35: 0 | J35: 0 | K35: 0 | L35: 1372890 | M35: 2960245
A36: Committed | B36: 0 | C36: 0 | D36: 0 | E36: 0 | F36: 0 | G36: 0 | H36: 0 | I36: 0 | J36: 0 | K36: 0 | L36: 0 | M36: 0
A37: Assigned | B37: 53108 | C37: 0 | D37: 0 | E37: 0 | F37: 0 | G37: 0 | H37: 0 | I37: 0 | J37: 0 | K37: 0 | L37: 0 | M37: 0
A38: Unassigned - Emergency Disaster Relief reserve | B38: 0 | C38: 0 | D38: 0 | E38: 0 | F38: 0 | G38: 0 | H38: 0 | I38: 0 | J38: 0 | K38: 0 | L38: 9000000 | M38: 7500000
A39: Unassigned - remaining | B39: 1008587 | C39: 1323100 | D39: 1713302 | E39: -186227 | F39: -2233507 | G39: -1707620 | H39: -1777532 | I39: 7117568 | J39: 16423835 | K39: 23034216 | L39: 12393697 | M39: 13614887
A40: Total fund balance | B40: =SUM(B34:B39) | C40: =SUM(C34:C39) | D40: =SUM(D34:D39) | E40: =SUM(E34:E39) | F40: =SUM(F34:F39) | G40: =SUM(G34:G39) | H40: =SUM(H34:H39) | I40: =SUM(I34:I39) | ... M40: =SUM(M34:M39)
A42: Total liabilities, deferred inflows and fund balance | B42: =B27+B31+B40 | C42: =C27+C31+C40 | D42: =D27+D31+D40 | E42: =E27+E31+E40 | F42: =F27+F31+F40 | G42: =G27+G31+G40 | H42: =H27+H31+H40 | I42: =I27+I31+I40 | ... M42: =M27+M31+M40
A44: Memo: working capital (assets less liabilities, excl. advances) | B44: =B18-B14-B15-B27 | C44: =C18-C14-C15-C27 | D44: =D18-D14-D15-D27 | E44: =E18-E14-E15-E27 | F44: =F18-F14-F15-F27 | G44: =G18-G14-G15-G27 | H44: =H18-H14-H15-H27 | I44: =I18-I14-I15-I27 | ... M44: =M18-M14-M15-M27
A45: Memo: unassigned fund balance incl. EDRF | B45: =B38+B39 | C45: =C38+C39 | D45: =D38+D39 | E45: =E38+E39 | F45: =F38+F39 | G45: =G38+G39 | H45: =H38+H39 | I45: =I38+I39 | ... M45: =M38+M39
A46: Memo: unassigned fund balance as % of expenditures | B46: =IFERROR(B45/GF_Operating_Statement!B34,0) | C46: =IFERROR(C45/GF_Operating_Statement!C34,0) | D46: =IFERROR(D45/GF_Operating_Statement!D34,0) | E46: =IFERROR(E45/GF_Operating_Statement!E34,0) | F46: =IFERROR(F45/GF_Operating_Statement!F34,0) | G46: =IFERROR(G45/GF_Operating_Statement!G34,0) | H46: =IFERROR(H45/GF_Operating_Statement!H34,0) | I46: =IFERROR(I45/GF_Operating_Statement!I34,0) | ... M46: =IFERROR(M45/GF_Operating_Statement!M34,0)
A48: Check: total assets per audited balance sheet | B48: 2454467 | C48: 3421573 | D48: 8386394 | E48: 8135750 | F48: 8913780 | G48: 9064693 | H48: 12974252 | I48: 18850962 | J48: 27620525 | K48: 28578584 | L48: 29043031 | M48: 30104863
...

Sheet GF_Cash_Flow_Derived
A1: City of El Cerrito - GENERAL FUND ONLY
A2: Statement of Cash Flows - DERIVED (indirect method, GASB 9 categories), $
A3: Not an audited statement: governmental funds do not report cash flows under GASB. Built from GF_Operating_Statement and year-over-year GF_Balance_Sheet changes. FY2014 omitted (needs the June 30, 2013 balance sheet); FY2026 omitted (no balance sheet yet).
A6: Fiscal year ended June 30 | B6: 2014 | C6: 2015 | D6: 2016 | E6: 2017 | F6: 2018 | G6: 2019 | H6: 2020 | I6: 2021 | J6: 2022 | K6: 2023 | L6: 2024 | M6: 2025
A7: CASH FLOWS FROM OPERATING ACTIVITIES
A8: Revenues less current (operating) expenditures | C8: =GF_Operating_Statement!C36+GF_Operating_Statement!C30+GF_Operating_Statement!C32+GF_Operating_Statement!C33 | D8: =GF_Operating_Statement!D36+GF_Operating_Statement!D30+GF_Operating_Statement!D32+GF_Operating_Statement!D33 | E8: =GF_Operating_Statement!E36+GF_Operating_Statement!E30+GF_Operating_Statement!E32+GF_Operating_Statement!E33 | F8: =GF_Operating_Statement!F36+GF_Operating_Statement!F30+GF_Operating_Statement!F32+GF_Operating_Statement!F33 | G8: =GF_Operating_Statement!G36+GF_Operating_Statement!G30+GF_Operating_Statement!G32+GF_Operating_Statement!G33 | H8: =GF_Operating_Statement!H36+GF_Operating_Statement!H30+GF_Operating_Statement!H32+GF_Operating_Statement!H33 | I8: =GF_Operating_Statement!I36+GF_Operating_Statement!I30+GF_Operating_Statement!I32+GF_Operating_Statement!I33 | J8: =GF_Operating_Statement!J36+GF_Operating_Statement!J30+GF_Operating_Statement!J32+GF_Operating_Statement!J33 | ... M8: =GF_Operating_Statement!M36+GF_Operating_Statement!M30+GF_Operating_Statement!M32+GF_Operating_Statement!M33
A9: (Increase) decrease in receivables (AR, interest, due from governments) | C9: =-(GF_Balance_Sheet!C10-GF_Balance_Sheet!B10+GF_Balance_Sheet!C11-GF_Balance_Sheet!B11+GF_Balance_Sheet!C12-GF_Balance_Sheet!B12) | D9: =-(GF_Balance_Sheet!D10-GF_Balance_Sheet!C10+GF_Balance_Sheet!D11-GF_Balance_Sheet!C11+GF_Balance_Sheet!D12-GF_Balance_Sheet!C12) | E9: =-(GF_Balance_Sheet!E10-GF_Balance_Sheet!D10+GF_Balance_Sheet!E11-GF_Balance_Sheet!D11+GF_Balance_Sheet!E12-GF_Balance_Sheet!D12) | F9: =-(GF_Balance_Sheet!F10-GF_Balance_Sheet!E10+GF_Balance_Sheet!F11-GF_Balance_Sheet!E11+GF_Balance_Sheet!F12-GF_Balance_Sheet!E12) | G9: =-(GF_Balance_Sheet!G10-GF_Balance_Sheet!F10+GF_Balance_Sheet!G11-GF_Balance_Sheet!F11+GF_Balance_Sheet!G12-GF_Balance_Sheet!F12) | H9: =-(GF_Balance_Sheet!H10-GF_Balance_Sheet!G10+GF_Balance_Sheet!H11-GF_Balance_Sheet!G11+GF_Balance_Sheet!H12-GF_Balance_Sheet!G12) | I9: =-(GF_Balance_Sheet!I10-GF_Balance_Sheet!H10+GF_Balance_Sheet!I11-GF_Balance_Sheet!H11+GF_Balance_Sheet!I12-GF_Balance_Sheet!H12) | J9: =-(GF_Balance_Sheet!J10-GF_Balance_Sheet!I10+GF_Balance_Sheet!J11-GF_Balance_Sheet!I11+GF_Balance_Sheet!J12-GF_Balance_Sheet!I12) | ... M9: =-(GF_Balance_Sheet!M10-GF_Balance_Sheet!L10+GF_Balance_Sheet!M11-GF_Balance_Sheet!L11+GF_Balance_Sheet!M12-GF_Balance_Sheet!L12)
A10: (Increase) decrease in inventory and prepaids | C10: =-(GF_Balance_Sheet!C16-GF_Balance_Sheet!B16+GF_Balance_Sheet!C17-GF_Balance_Sheet!B17) | D10: =-(GF_Balance_Sheet!D16-GF_Balance_Sheet!C16+GF_Balance_Sheet!D17-GF_Balance_Sheet!C17) | E10: =-(GF_Balance_Sheet!E16-GF_Balance_Sheet!D16+GF_Balance_Sheet!E17-GF_Balance_Sheet!D17) | F10: =-(GF_Balance_Sheet!F16-GF_Balance_Sheet!E16+GF_Balance_Sheet!F17-GF_Balance_Sheet!E17) | G10: =-(GF_Balance_Sheet!G16-GF_Balance_Sheet!F16+GF_Balance_Sheet!G17-GF_Balance_Sheet!F17) | H10: =-(GF_Balance_Sheet!H16-GF_Balance_Sheet!G16+GF_Balance_Sheet!H17-GF_Balance_Sheet!G17) | I10: =-(GF_Balance_Sheet!I16-GF_Balance_Sheet!H16+GF_Balance_Sheet!I17-GF_Balance_Sheet!H17) | J10: =-(GF_Balance_Sheet!J16-GF_Balance_Sheet!I16+GF_Balance_Sheet!J17-GF_Balance_Sheet!I17) | ... M10: =-(GF_Balance_Sheet!M16-GF_Balance_Sheet!L16+GF_Balance_Sheet!M17-GF_Balance_Sheet!L17)
A11: Increase (decrease) in accounts payable and accrued liabilities | C11: =(GF_Balance_Sheet!C21-GF_Balance_Sheet!B21+GF_Balance_Sheet!C22-GF_Balance_Sheet!B22) | D11: =(GF_Balance_Sheet!D21-GF_Balance_Sheet!C21+GF_Balance_Sheet!D22-GF_Balance_Sheet!C22) | E11: =(GF_Balance_Sheet!E21-GF_Balance_Sheet!D21+GF_Balance_Sheet!E22-GF_Balance_Sheet!D22) | F11: =(GF_Balance_Sheet!F21-GF_Balance_Sheet!E21+GF_Balance_Sheet!F22-GF_Balance_Sheet!E22) | G11: =(GF_Balance_Sheet!G21-GF_Balance_Sheet!F21+GF_Balance_Sheet!G22-GF_Balance_Sheet!F22) | H11: =(GF_Balance_Sheet!H21-GF_Balance_Sheet!G21+GF_Balance_Sheet!H22-GF_Balance_Sheet!G22) | I11: =(GF_Balance_Sheet!I21-GF_Balance_Sheet!H21+GF_Balance_Sheet!I22-GF_Balance_Sheet!H22) | J11: =(GF_Balance_Sheet!J21-GF_Balance_Sheet!I21+GF_Balance_Sheet!J22-GF_Balance_Sheet!I22) | ... M11: =(GF_Balance_Sheet!M21-GF_Balance_Sheet!L21+GF_Balance_Sheet!M22-GF_Balance_Sheet!L22)
A12: Increase (decrease) in deposits payable | C12: =(GF_Balance_Sheet!C24-GF_Balance_Sheet!B24) | D12: =(GF_Balance_Sheet!D24-GF_Balance_Sheet!C24) | E12: =(GF_Balance_Sheet!E24-GF_Balance_Sheet!D24) | F12: =(GF_Balance_Sheet!F24-GF_Balance_Sheet!E24) | G12: =(GF_Balance_Sheet!G24-GF_Balance_Sheet!F24) | H12: =(GF_Balance_Sheet!H24-GF_Balance_Sheet!G24) | I12: =(GF_Balance_Sheet!I24-GF_Balance_Sheet!H24) | J12: =(GF_Balance_Sheet!J24-GF_Balance_Sheet!I24) | ... M12: =(GF_Balance_Sheet!M24-GF_Balance_Sheet!L24)
A13: Increase (decrease) in unearned revenue and unavailable revenue | C13: =(GF_Balance_Sheet!C25-GF_Balance_Sheet!B25+GF_Balance_Sheet!C30-GF_Balance_Sheet!B30) | D13: =(GF_Balance_Sheet!D25-GF_Balance_Sheet!C25+GF_Balance_Sheet!D30-GF_Balance_Sheet!C30) | E13: =(GF_Balance_Sheet!E25-GF_Balance_Sheet!D25+GF_Balance_Sheet!E30-GF_Balance_Sheet!D30) | F13: =(GF_Balance_Sheet!F25-GF_Balance_Sheet!E25+GF_Balance_Sheet!F30-GF_Balance_Sheet!E30) | G13: =(GF_Balance_Sheet!G25-GF_Balance_Sheet!F25+GF_Balance_Sheet!G30-GF_Balance_Sheet!F30) | H13: =(GF_Balance_Sheet!H25-GF_Balance_Sheet!G25+GF_Balance_Sheet!H30-GF_Balance_Sheet!G30) | I13: =(GF_Balance_Sheet!I25-GF_Balance_Sheet!H25+GF_Balance_Sheet!I30-GF_Balance_Sheet!H30) | J13: =(GF_Balance_Sheet!J25-GF_Balance_Sheet!I25+GF_Balance_Sheet!J30-GF_Balance_Sheet!I30) | ... M13: =(GF_Balance_Sheet!M25-GF_Balance_Sheet!L25+GF_Balance_Sheet!M30-GF_Balance_Sheet!L30)
A14: Net cash provided (used) by operating activities | C14: =SUM(C8:C13) | D14: =SUM(D8:D13) | E14: =SUM(E8:E13) | F14: =SUM(F8:F13) | G14: =SUM(G8:G13) | H14: =SUM(H8:H13) | I14: =SUM(I8:I13) | J14: =SUM(J8:J13) | ... M14: =SUM(M8:M13)
A16: CASH FLOWS FROM NONCAPITAL FINANCING ACTIVITIES
A17: Transfers in | C17: =GF_Operating_Statement!C39 | D17: =GF_Operating_Statement!D39 | E17: =GF_Operating_Statement!E39 | F17: =GF_Operating_Statement!F39 | G17: =GF_Operating_Statement!G39 | H17: =GF_Operating_Statement!H39 | I17: =GF_Operating_Statement!I39 | J17: =GF_Operating_Statement!J39 | ... M17: =GF_Operating_Statement!M39
A18: Transfers out | C18: =GF_Operating_Statement!C40 | D18: =GF_Operating_Statement!D40 | E18: =GF_Operating_Statement!E40 | F18: =GF_Operating_Statement!F40 | G18: =GF_Operating_Statement!G40 | H18: =GF_Operating_Statement!H40 | I18: =GF_Operating_Statement!I40 | J18: =GF_Operating_Statement!J40 | ... M18: =GF_Operating_Statement!M40
A19: Special items | C19: =GF_Operating_Statement!C46 | D19: =GF_Operating_Statement!D46 | E19: =GF_Operating_Statement!E46 | F19: =GF_Operating_Statement!F46 | G19: =GF_Operating_Statement!G46 | H19: =GF_Operating_Statement!H46 | I19: =GF_Operating_Statement!I46 | J19: =GF_Operating_Statement!J46 | ... M19: =GF_Operating_Statement!M46
A20: Net change in interfund balances and advances | C20: =-(GF_Balance_Sheet!C13-GF_Balance_Sheet!B13+GF_Balance_Sheet!C14-GF_Balance_Sheet!B14+GF_Balance_Sheet!C15-GF_Balance_Sheet!B15)+(GF_Balance_Sheet!C23-GF_Balance_Sheet!B23) | D20: =-(GF_Balance_Sheet!D13-GF_Balance_Sheet!C13+GF_Balance_Sheet!D14-GF_Balance_Sheet!C14+GF_Balance_Sheet!D15-GF_Balance_Sheet!C15)+(GF_Balance_Sheet!D23-GF_Balance_Sheet!C23) | E20: =-(GF_Balance_Sheet!E13-GF_Balance_Sheet!D13+GF_Balance_Sheet!E14-GF_Balance_Sheet!D14+GF_Balance_Sheet!E15-GF_Balance_Sheet!D15)+(GF_Balance_Sheet!E23-GF_Balance_Sheet!D23) | F20: =-(GF_Balance_Sheet!F13-GF_Balance_Sheet!E13+GF_Balance_Sheet!F14-GF_Balance_Sheet!E14+GF_Balance_Sheet!F15-GF_Balance_Sheet!E15)+(GF_Balance_Sheet!F23-GF_Balance_Sheet!E23) | G20: =-(GF_Balance_Sheet!G13-GF_Balance_Sheet!F13+GF_Balance_Sheet!G14-GF_Balance_Sheet!F14+GF_Balance_Sheet!G15-GF_Balance_Sheet!F15)+(GF_Balance_Sheet!G23-GF_Balance_Sheet!F23) | H20: =-(GF_Balance_Sheet!H13-GF_Balance_Sheet!G13+GF_Balance_Sheet!H14-GF_Balance_Sheet!G14+GF_Balance_Sheet!H15-GF_Balance_Sheet!G15)+(GF_Balance_Sheet!H23-GF_Balance_Sheet!G23) | I20: =-(GF_Balance_Sheet!I13-GF_Balance_Sheet!H13+GF_Balance_Sheet!I14-GF_Balance_Sheet!H14+GF_Balance_Sheet!I15-GF_Balance_Sheet!H15)+(GF_Balance_Sheet!I23-GF_Balance_Sheet!H23) | J20: =-(GF_Balance_Sheet!J13-GF_Balance_Sheet!I13+GF_Balance_Sheet!J14-GF_Balance_Sheet!I14+GF_Balance_Sheet!J15-GF_Balance_Sheet!I15)+(GF_Balance_Sheet!J23-GF_Balance_Sheet!I23) | ... M20: =-(GF_Balance_Sheet!M13-GF_Balance_Sheet!L13+GF_Balance_Sheet!M14-GF_Balance_Sheet!L14+GF_Balance_Sheet!M15-GF_Balance_Sheet!L15)+(GF_Balance_Sheet!M23-GF_Balance_Sheet!L23)
A21: Short-term notes (TRAN) issued (repaid), net | C21: =(GF_Balance_Sheet!C26-GF_Balance_Sheet!B26) | D21: =(GF_Balance_Sheet!D26-GF_Balance_Sheet!C26) | E21: =(GF_Balance_Sheet!E26-GF_Balance_Sheet!D26) | F21: =(GF_Balance_Sheet!F26-GF_Balance_Sheet!E26) | G21: =(GF_Balance_Sheet!G26-GF_Balance_Sheet!F26) | H21: =(GF_Balance_Sheet!H26-GF_Balance_Sheet!G26) | I21: =(GF_Balance_Sheet!I26-GF_Balance_Sheet!H26) | J21: =(GF_Balance_Sheet!J26-GF_Balance_Sheet!I26) | ... M21: =(GF_Balance_Sheet!M26-GF_Balance_Sheet!L26)
A22: Net cash provided (used) by noncapital financing activities | C22: =SUM(C17:C21) | D22: =SUM(D17:D21) | E22: =SUM(E17:E21) | F22: =SUM(F17:F21) | G22: =SUM(G17:G21) | H22: =SUM(H17:H21) | I22: =SUM(I17:I21) | J22: =SUM(J17:J21) | ... M22: =SUM(M17:M21)
A24: CASH FLOWS FROM CAPITAL AND RELATED FINANCING ACTIVITIES
A25: Capital outlay | C25: =-GF_Operating_Statement!C30 | D25: =-GF_Operating_Statement!D30 | E25: =-GF_Operating_Statement!E30 | F25: =-GF_Operating_Statement!F30 | G25: =-GF_Operating_Statement!G30 | H25: =-GF_Operating_Statement!H30 | I25: =-GF_Operating_Statement!I30 | J25: =-GF_Operating_Statement!J30 | ... M25: =-GF_Operating_Statement!M30
A26: Principal paid on debt and leases | C26: =-GF_Operating_Statement!C32 | D26: =-GF_Operating_Statement!D32 | E26: =-GF_Operating_Statement!E32 | F26: =-GF_Operating_Statement!F32 | G26: =-GF_Operating_Statement!G32 | H26: =-GF_Operating_Statement!H32 | I26: =-GF_Operating_Statement!I32 | J26: =-GF_Operating_Statement!J32 | ... M26: =-GF_Operating_Statement!M32
A27: Interest and fiscal charges paid | C27: =-GF_Operating_Statement!C33 | D27: =-GF_Operating_Statement!D33 | E27: =-GF_Operating_Statement!E33 | F27: =-GF_Operating_Statement!F33 | G27: =-GF_Operating_Statement!G33 | H27: =-GF_Operating_Statement!H33 | I27: =-GF_Operating_Statement!I33 | J27: =-GF_Operating_Statement!J33 | ... M27: =-GF_Operating_Statement!M33
